Workbook

Sheet Data Perhitungan
A16: Waktu (t) | B16: EFB 10 mm (Ct1) | C16: Orde 1 (Ct2) | D16: Error 1 | E16: Error^2 1 | F16: Orde 2 (Ct3) | G16: Error 2 | H16: Error^2 2
A17: 0 | B17: 0
A18: 5 | B18: 127 | C18: =A27*(1-EXP((-B27)*A18)) -> 57.525218 | D18: =B18-C18 -> 69.474782 | E18: =D18^2 -> 4826.7454 | F18: =(C27*A18*A27^2)/(1+C27*A18*A27) -> 144.22699 | G18: =B18-F18 -> -17.226991 | H18: =G18^2 -> 296.7692
A19: 10 | B19: 133.2 | C19: =A27*(1-EXP((-B27)*A19)) -> 92.416026 | D19: =B19-C19 -> 40.783974 | E19: =D19^2 -> 1663.3326 | F19: =(C27*A19*A27^2)/(1+C27*A19*A27) -> 145.20679 | G19: =B19-F19 -> -12.006793 | H19: =G19^2 -> 144.16309
A20: 15 | B20: 134.6 | C20: =A27*(1-EXP((-B27)*A20)) -> 113.57837 | D20: =B20-C20 -> 21.021629 | E20: =D20^2 -> 441.9089 | F20: =(C27*A20*A27^2)/(1+C27*A20*A27) -> 145.53636 | G20: =B20-F20 -> -10.93636 | H20: =G20^2 -> 119.60396
A21: 20 | B21: 139 | C21: =A27*(1-EXP((-B27)*A21)) -> 126.41398 | D21: =B21-C21 -> 12.586018 | E21: =D21^2 -> 158.40786 | F21: =(C27*A21*A27^2)/(1+C27*A21*A27) -> 145.7017 | G21: =B21-F21 -> -6.7017042 | H21: =G21^2 -> 44.912839
A22: 25 | B22: 143.8 | C22: =A27*(1-EXP((-B27)*A22)) -> 134.19917 | D22: =B22-C22 -> 9.6008268 | E22: =D22^2 -> 92.175875 | F22: =(C27*A22*A27^2)/(1+C27*A22*A27) -> 145.80109 | G22: =B22-F22 -> -2.0010914 | H22: =G22^2 -> 4.0043668
A23: 30 | B23: 146.2 | C23: =A27*(1-EXP((-B27)*A23)) -> 138.92113 | D23: =B23-C23 -> 7.2788694 | E23: =D23^2 -> 52.98194 | F23: =(C27*A23*A27^2)/(1+C27*A23*A27) -> 145.86742 | G23: =B23-F23 -> 0.33257507 | H23: =G23^2 -> 0.11060618
A25: Asumsi | E25: SSE Orde 1 | F25: SSE Orde 1 (Setelah Solver) | H25: SSE Orde 2 | I25: SSE Orde 2 (Setelah solver)
A26: Csat | B26: K1 | C26: K2 | E26: =SUM(E18:E23) -> 7235.5525 | F26: 280.37576 | H26: =SUM(H18:H23) -> 609.56406 | I26: 43.969082
A27: 146.2 | B27: 0.1 | C27: 0.1
A29: Hasil
A30: K1 | B30: K2
A31: 0.36902977 | B31: 0.008233212
A35: Waktu (t) | B35: EFB 2 mm (Ct1) | C35: Orde 1 (Ct1) | D35: Error 1 | E35: Error^2 1 | F35: Orde 2 (Ct3) | G35: Error 2 | H35: Error^2 2
A36: 0 | B36: 0
A37: 5 | B37: 115.5 | C37: =A46*(1-EXP(-B46)*A37) -> -429.59841 | D37: =B37-C37 -> 545.09841 | E37: =D37^2 -> 297132.27 | F37: =(C46*A37*A46^2)/(1+C46*A37*A46) -> 119.93228 | G37: =B37-F37 -> -4.4322841 | H37: =G37^2 -> 19.645142
A38: 10 | B38: 115.7 | C38: =A46*(1-EXP(-B46)*A38) -> -981.09681 | D38: =B38-C38 -> 1096.7968 | E38: =D38^2 -> 1202963.2 | F38: =(C46*A38*A46^2)/(1+C46*A38*A46) -> 120.90814 | G38: =B38-F38 -> -5.2081367 | H38: =G38^2 -> 27.124688
A39: 15 | B39: 120.2 | C39: =A46*(1-EXP(-B46)*A39) -> -1532.5952 | D39: =B39-C39 -> 1652.7952 | E39: =D39^2 -> 2731732 | F39: =(C46*A39*A46^2)/(1+C46*A39*A46) -> 121.23696 | G39: =B39-F39 -> -1.0369595 | H39: =G39^2 -> 1.075285
A40: 20 | B40: 120.2 | C40: =A46*(1-EXP(-B46)*A40) -> -2084.0936 | D40: =B40-C40 -> 2204.2936 | E40: =D40^2 -> 4858910.4 | F40: =(C46*A40*A46^2)/(1+C46*A40*A46) -> 121.40204 | G40: =B40-F40 -> -1.2020425 | H40: =G40^2 -> 1.4449061
A41: 25 | B41: 121.6 | C41: =A46*(1-EXP(-B46)*A41) -> -2635.592 | D41: =B41-C41 -> 2757.192 | E41: =D41^2 -> 7602107.9 | F41: =(C46*A41*A46^2)/(1+C46*A41*A46) -> 121.50131 | G41: =B41-F41 -> 0.098691742 | H41: =G41^2 -> 0.0097400599
A42: 30 | B42: 121.9 | C42: =A46*(1-EXP(-B46)*A42) -> -3187.0904 | D42: =B42-C42 -> 3308.9904 | E42: =D42^2 -> 10949418 | F42: =(C46*A42*A46^2)/(1+C46*A42*A46) -> 121.56758 | G42: =B42-F42 -> 0.33242433 | H42: =G42^2 -> 0.11050593
A44: Asumsi | E44: SSE Orde 1 | F44: SSE Orde 1(Setelah Solver) | H44: SSE Orde 2 | I44: SSE Orde 2 (Setelah Solver)
A45: Csat | B45: K1 | C45: K2 | E45: =SUM(E37:E42) -> 27642264 | F45: 73.876154 | H45: =SUM(H37:H42) -> 49.410267 | I45: 10.510184
A46: 121.9 | B46: 0.1 | C46: 0.1
A48: Hasil
A49: K1 | B49: K2
A50: 7.451532 | B50: 0.026937232
A54: Waktu (t) | B54: EFB 0.85 mm (Ct1) | C54: Orde 1 (Ct2) | D54: Error 1 | E54: Error^2 1 | F54: Orde 2 (Ct3) | G54: Error 2 | H54: Error^2 2
A55: 0 | B55: 0
A56: 5 | B56: 94.7 | C56: =A65*(1-EXP(-B65)*A56) -> -467.30721 | D56: =B56-C56 -> 562.00721 | E56: =D56^2 -> 315852.1 | F56: =(C65*A56*A65^2)/(1+C65*A56*A65) -> 130.62972 | G56: =B56-F56 -> -35.929718 | H56: =G56^2 -> 1290.9446
A57: 10 | B57: 124.8 | C57: =A65*(1-EXP(-B65)*A57) -> -1067.2144 | D57: =B57-C57 -> 1192.0144 | E57: =D57^2 -> 1420898.4 | F57: =(C65*A57*A65^2)/(1+C65*A57*A65) -> 131.60749 | G57: =B57-F57 -> -6.807485 | H57: =G57^2 -> 46.341852
A58: 15 | B58: 124.4 | C58: =A65*(1-EXP(-B65)*A58) -> -1667.1216 | D58: =B58-C58 -> 1791.5216 | E58: =D58^2 -> 3209549.7 | F58: =(C65*A58*A65^2)/(1+C65*A58*A65) -> 131.93667 | G58: =B58-F58 -> -7.5366683 | H58: =G58^2 -> 56.80137
A59: 20 | B59: 125.1 | C59: =A65*(1-EXP(-B65)*A59) -> -2267.0288 | D59: =B59-C59 -> 2392.1288 | E59: =D59^2 -> 5722280.4 | F59: =(C65*A59*A65^2)/(1+C65*A59*A65) -> 132.10188 | G59: =B59-F59 -> -7.0018783 | H59: =G59^2 -> 49.0263
A60: 25 | B60: 125.7 | C60: =A65*(1-EXP(-B65)*A60) -> -2866.936 | D60: =B60-C60 -> 2992.636 | E60: =D60^2 -> 8955870.5 | F60: =(C65*A60*A65^2)/(1+C65*A60*A65) -> 132.2012 | G60: =B60-F60 -> -6.501203 | H60: =G60^2 -> 42.265641
A61: 30 | B61: 132.6 | C61: =A65*(1-EXP(-B65)*A61) -> -3466.8432 | D61: =B61-C61 -> 3599.4432 | E61: =D61^2 -> 12955992 | F61: =(C65*A61*A65^2)/(1+C65*A61*A65) -> 132.2675 | G61: =B61-F61 -> 0.33249749 | H61: =G61^2 -> 0.11055458
A63: Asumsi | E63: SSE Orde 1 | F63: SSE Orde 1 (Setelah Solver) | H63: SSE Orde 2 | I63: SSE Orde 2 (Setelah Solver)
A64: Csat | B64: K1 | C64: K2 | E64: =SUM(E56:E61) -> 32580443 | F64: 1444.8911 | H64: =SUM(H56:H61) -> 1485.4903 | I64: 197.1445
A65: 132.6 | B65: 0.1 | C65: 0.1
A67: Hasil
...

Sheet Hasil EFB 10mm
D1: Calcium
A2: Time (min) | B2: Concentration EFB 10mm (Ct1) | C2: Orde 1 (Ct2) | D2: Error 1 | E2: Error^2 1 | F2: Orde 2 (Ct3) | G2: Error 2 | H2: Error 2^2 | J2: Csat | K2: 146.2
A3: 0 | B3: 0 | C3: 0 | D3: 0 | E3: 0 | F3: 0 | G3: 0 | H3: 0 | J3: K1 | K3: 0.36902977
A4: 5 | B4: 127 | C4: =K2*(1-EXP(-K3*A4)) -> 123.10014 | D4: =B4-C4 -> 3.8998628 | E4: =D4^2 -> 15.20893 | F4: =(K4*A4*K2^2)/(1+K4*A4*K2) -> 125.36927 | G4: =B4-F4 -> 1.6307272 | H4: =G4^2 -> 2.6592712 | J4: K2 | K4: 0.008233212
A5: 10 | B5: 133.2 | C5: =K2*(1-EXP(-K3*A5)) -> 142.55018 | D5: =B5-C5 -> -9.3501801 | E5: =D5^2 -> 87.425869 | F5: =(K4*A5*K2^2)/(1+K4*A5*K2) -> 134.98573 | G5: =B5-F5 -> -1.7857257 | H5: =G5^2 -> 3.1888163 | J5: SSE Orde 1 | K5: =SUM(E3:E9) -> 280.37576
A6: 15 | B6: 134.6 | C6: =K2*(1-EXP(-K3*A6)) -> 145.62332 | D6: =B6-C6 -> -11.023322 | E6: =D6^2 -> 121.51363 | F6: =(K4*A6*K2^2)/(1+K4*A6*K2) -> 138.52765 | G6: =B6-F6 -> -3.9276478 | H6: =G6^2 -> 15.426417 | J6: SSE Orde 2 | K6: =SUM(H3:H9) -> 43.969082
A7: 20 | B7: 139 | C7: =K2*(1-EXP(-K3*A7)) -> 146.10888 | D7: =B7-C7 -> -7.1088838 | E7: =D7^2 -> 50.536229 | F7: =(K4*A7*K2^2)/(1+K4*A7*K2) -> 140.36924 | G7: =B7-F7 -> -1.3692385 | H7: =G7^2 -> 1.8748141 | J7: SST Orde 1 | K7: {=SUM((Table4[Concentration EFB 10mm (Ct1)]-AVERAGE(Table4[Concentration EFB 10mm (Ct1)]))^2)} -> 16412.789
A8: 25 | B8: 143.8 | C8: =K2*(1-EXP(-K3*A8)) -> 146.1856 | D8: =B8-C8 -> -2.3856035 | E8: =D8^2 -> 5.691104 | F8: =(K4*A8*K2^2)/(1+K4*A8*K2) -> 141.49788 | G8: =B8-F8 -> 2.3021152 | H8: =G8^2 -> 5.2997346 | J8: SST Orde 2 | K8: {=SUM((Table4[Concentration EFB 10mm (Ct1)]-AVERAGE(Table4[Concentration EFB 10mm (Ct1)]))^2)} -> 16412.789
A9: 30 | B9: 146.2 | C9: =K2*(1-EXP(-K3*A9)) -> 146.19773 | D9: =B9-C9 -> 0.002274676 | E9: =D9^2 -> 5.1741509e-06 | F9: =(K4*A9*K2^2)/(1+K4*A9*K2) -> 142.26045 | G9: =B9-F9 -> 3.9395468 | H9: =G9^2 -> 15.520029 | J9: R^2 Orde 1 | K9: =1-(K5/K7) -> 0.98291724
J10: R^2 Orde 2 | K10: =1-(K6/K8) -> 0.99732105
D27: Sulfur
A28: Time (min) | B28: Concentration (Ct1) | C28: Orde 1 (Ct2) | D28: Error 1 | E28: Error^2 1 | F28: Orde 2 (Ct2) | G28: Error 2 | H28: Error^2 2 | J28: Csat | K28: 7.4
A29: 0 | B29: 0 | C29: 0 | D29: 0 | E29: 0 | F29: 0 | G29: 0 | H29: 0 | J29: K1 | K29: 7.4
A30: 5 | B30: 7 | C30: =K28*(1-EXP(-K29*B30)) -> 7.4 | D30: =B30-C30 -> -0.4 | E30: =D30^2 -> 0.16 | F30: =(K30*B30*K28^2)/(1+K30*B30*K28) -> 7.1914894 | G30: =B30-F30 -> -0.19148936 | H30: =G30^2 -> 0.036668176 | J30: K2 | K30: 0.66582618
A31: 10 | B31: 7.1 | C31: =K28*(1-EXP(-K29*B31)) -> 7.4 | D31: =B31-C31 -> -0.3 | E31: =D31^2 -> 0.09 | F31: =(K30*B31*K28^2)/(1+K30*B31*K28) -> 7.1943445 | G31: =B31-F31 -> -0.094344515 | H31: =G31^2 -> 0.0089008875 | J31: SSE Orde 1 | K31: =SUM(E29:E35) -> 0.38
A32: 15 | B32: 7.1 | C32: =K28*(1-EXP(-K29*B32)) -> 7.4 | D32: =B32-C32 -> -0.3 | E32: =D32^2 -> 0.09 | F32: =(K30*B32*K28^2)/(1+K30*B32*K28) -> 7.1943445 | G32: =B32-F32 -> -0.094344515 | H32: =G32^2 -> 0.0089008875 | J32: SSE Orde 2 | K32: =SUM(H29:H35) -> 0.13252286
A33: 20 | B33: 7.2 | C33: =K28*(1-EXP(-K29*B33)) -> 7.4 | D33: =B33-C33 -> -0.2 | E33: =D33^2 -> 0.04 | F33: =(K30*B33*K28^2)/(1+K30*B33*K28) -> 7.1971225 | G33: =B33-F33 -> 0.0028774673 | H33: =G33^2 -> 8.2798181e-06 | J33: SST Orde 1 | K33: {=SUM((B29:B35-AVERAGE(B29:B35))^2)} -> 44.574286
A34: 25 | B34: 7.4 | C34: =K28*(1-EXP(-K29*B34)) -> 7.4 | D34: =B34-C34 -> 0 | E34: =D34^2 -> 0 | F34: =(K30*B34*K28^2)/(1+K30*B34*K28) -> 7.2024593 | G34: =B34-F34 -> 0.19754066 | H34: =G34^2 -> 0.039022314 | J34: SST Orde 2 | K34: {=SUM((B29:B35-AVERAGE(B29:B35))^2)} -> 44.574286
A35: 30 | B35: 7.4 | C35: =K28*(1-EXP(-K29*B35)) -> 7.4 | D35: =B35-C35 -> 0 | E35: =D35^2 -> 0 | F35: =(K30*B35*K28^2)/(1+K30*B35*K28) -> 7.2024593 | G35: =B35-F35 -> 0.19754066 | H35: =G35^2 -> 0.039022314 | J35: R^2 Orde 1 | K35: =1-(K31/K33) -> 0.99147491
J36: R^2 Orde 2 | K36: =1-(K32/K34) -> 0.99702692
D54: Magnesium
A55: Time (min) | B55: Concentration (Ct1) | C55: Orde 1 (Ct2) | D55: Error 1 | E55: Error^2 1 | F55: Orde 2 (Ct3) | G55: Error 2 | H55: Error^2 2 | J55: Csat | K55: 97.3
A56: 0 | B56: 0 | C56: 0 | D56: 0 | E56: 0 | F56: 0 | G56: 0 | H56: 0 | J56: K1 | K56: 6.2060965
A57: 5 | B57: 69.6 | C57: =K55*(1-EXP(-K56*A57)) -> 97.3 | D57: =B57-C57 -> -27.7 | E57: =D57^2 -> 767.29 | F57: =(K57*A57*K55^2)/(1+K57*A57*K55) -> 75.685978 | G57: =B57-F57 -> -6.0859782 | H57: =G57^2 -> 37.039131 | J57: K2 | K57: 0.007197754
A58: 10 | B58: 89 | C58: =K55*(1-EXP(-K56*A58)) -> 97.3 | D58: =B58-C58 -> -8.3 | E58: =D58^2 -> 68.89 | F58: =(K57*A58*K55^2)/(1+K57*A58*K55) -> 85.142689 | G58: =B58-F58 -> 3.8573109 | H58: =G58^2 -> 14.878847 | J58: SSE Orde 1 | K58: =SUM(E56:E62) -> 913.54
A59: 15 | B59: 90.7 | C59: =K55*(1-EXP(-K56*A59)) -> 97.3 | D59: =B59-C59 -> -6.6 | E59: =D59^2 -> 43.56 | F59: =(K57*A59*K55^2)/(1+K57*A59*K55) -> 88.842897 | G59: =B59-F59 -> 1.8571029 | H59: =G59^2 -> 3.4488311 | J59: SSE Orde 2 | K59: =SUM(H56:H62) -> 98.967365
A60: 20 | B60: 91.5 | C60: =K55*(1-EXP(-K56*A60)) -> 97.3 | D60: =B60-C60 -> -5.8 | E60: =D60^2 -> 33.64 | F60: =(K57*A60*K55^2)/(1+K57*A60*K55) -> 90.816285 | G60: =B60-F60 -> 0.68371473 | H60: =G60^2 -> 0.46746584 | J60: SST Orde 1 | K60: {=SUM((B56:B62-AVERAGE(B56:B62))^2)} -> 7331.5143
A61: 25 | B61: 96.9 | C61: =K55*(1-EXP(-K56*A61)) -> 97.3 | D61: =B61-C61 -> -0.4 | E61: =D61^2 -> 0.16 | F61: =(K57*A61*K55^2)/(1+K57*A61*K55) -> 92.042966 | G61: =B61-F61 -> 4.8570337 | H61: =G61^2 -> 23.590776 | J61: SST Orde 2 | K61: {=SUM((B56:B62-AVERAGE(B56:B62))^2)} -> 7331.5143
A62: 30 | B62: 97.3 | C62: =K55*(1-EXP(-K56*A62)) -> 97.3 | D62: =B62-C62 -> 0 | E62: =D62^2 -> 0 | F62: =(K57*A62*K55^2)/(1+K57*A62*K55) -> 92.879331 | G62: =B62-F62 -> 4.4206689 | H62: =G62^2 -> 19.542313 | J62: R^2 Orde 1 | K62: =1-(K58/K60) -> 0.87539546
J63: R^2 Orde 2 | K63: =1-(K59/K61) -> 0.9865011
D81: Silicon
A82: Time (min) | B82: Concentration (Ct1) | C82: Orde 1 (Ct2) | D82: Error 1 | E82: Error^2 1 | F82: Orde 2 (Ct3) | G82: Error 2 | H82: Error^2 2 | J82: Csat | K82: 5.19
A83: 0 | B83: 0 | C83: 0 | D83: 0 | E83: 0 | F83: 0 | G83: 0 | H83: 0 | J83: K1 | K83: 5.6388017
A84: 5 | B84: 2.09 | C84: =K82*(1-EXP(-K83*A84)) -> 5.19 | D84: =B84-C84 -> -3.1 | E84: =D84^2 -> 9.61 | F84: =(K84*A84*K82^2)/(1+K84*A84*K82) -> 3.1274555 | G84: =B84-F84 -> -1.0374555 | H84: =G84^2 -> 1.0763139 | J84: K2 | K84: 0.05843196
A85: 10 | B85: 4.19 | C85: =K82*(1-EXP(-K83*A85)) -> 5.19 | D85: =B85-C85 -> -1 | E85: =D85^2 -> 1 | F85: =(K84*A85*K82^2)/(1+K84*A85*K82) -> 3.9029951 | G85: =B85-F85 -> 0.28700489 | H85: =G85^2 -> 0.082371804 | J85: SSE Orde 1 | K85: =SUM(E83:E89) -> 11.27
A86: 15 | B86: 4.39 | C86: =K82*(1-EXP(-K83*A86)) -> 5.19 | D86: =B86-C86 -> -0.8 | E86: =D86^2 -> 0.64 | F86: =(K84*A86*K82^2)/(1+K84*A86*K82) -> 4.2546842 | G86: =B86-F86 -> 0.13531578 | H86: =G86^2 -> 0.01831036 | J86: SSE Orde 2 | K86: =SUM(H83:H89) -> 2.0986657
A87: 20 | B87: 5.09 | C87: =K82*(1-EXP(-K83*A87)) -> 5.19 | D87: =B87-C87 -> -0.1 | E87: =D87^2 -> 0.01 | F87: =(K84*A87*K82^2)/(1+K84*A87*K82) -> 4.4554175 | G87: =B87-F87 -> 0.63458253 | H87: =G87^2 -> 0.40269499 | J87: SST Orde 1 | K87: {=SUM((B83:B89-AVERAGE(B83:B89))^2)} -> 23.0798
A88: 25 | B88: 5.09 | C88: =K82*(1-EXP(-K83*A88)) -> 5.19 | D88: =B88-C88 -> -0.1 | E88: =D88^2 -> 0.01 | F88: =(K84*A88*K82^2)/(1+K84*A88*K82) -> 4.5852139 | G88: =B88-F88 -> 0.50478607 | H88: =G88^2 -> 0.25480898 | J88: SST Orde 2 | K88: {=SUM((B83:B89-AVERAGE(B83:B89))^2)} -> 23.0798
A89: 30 | B89: 5.19 | C89: =K82*(1-EXP(-K83*A89)) -> 5.19 | D89: =B89-C89 -> 0 | E89: =D89^2 -> 0 | F89: =(K84*A89*K82^2)/(1+K84*A89*K82) -> 4.6760295 | G89: =B89-F89 -> 0.51397048 | H89: =G89^2 -> 0.26416566 | J89: R^2 Orde 1 | K89: =1-(K85/K87) -> 0.51169421
J90: R^2 Orde 2 | K90: =1-(K86/K88) -> 0.90906915
...

Sheet Hasil EFB 2mm
D1: Calcium
A2: Time (min) | B2: Concentration EFB 2 mm (Ct1) | C2: Orde 1 (Ct2) | D2: Error 1 | E2: Error^2 1 | F2: Orde 2 (Ct3) | G2: Error 2 | H2: Error^2 2 | J2: Csat | K2: 121.9
A3: 0 | B3: 0 | C3: 0 | D3: 0 | E3: 0 | F3: 0 | G3: 0 | H3: 0 | J3: K1 | K3: 0.56885347
A4: 5 | B4: 115.5 | C4: =K2*(1-EXP(-K3*A4)) -> 114.80824 | D4: =B4-C4 -> 0.69176092 | E4: =D4^2 -> 0.47853317 | F4: =(K4*A4*K2^2)/(1+K4*A4*K2) -> 114.90159 | G4: =B4-F4 -> 0.59840959 | H4: =G4^2 -> 0.35809403 | J4: K2 | K4: 0.026937232
A5: 10 | B5: 115.7 | C5: =K2*(1-EXP(-K3*A5)) -> 121.48742 | D5: =B5-C5 -> -5.7874235 | E5: =D5^2 -> 33.494271 | F5: =(K4*A5*K2^2)/(1+K4*A5*K2) -> 118.29738 | G5: =B5-F5 -> -2.5973801 | H5: =G5^2 -> 6.7463832 | J5: SSE Orde 1 | K5: =SUM(E3:E9) -> 39.756978
A6: 15 | B6: 120.2 | C6: =K2*(1-EXP(-K3*A6)) -> 121.876 | D6: =B6-C6 -> -1.6759976 | E6: =D6^2 -> 2.8089679 | F6: =(K4*A6*K2^2)/(1+K4*A6*K2) -> 119.47436 | G6: =B6-F6 -> 0.72564235 | H6: =G6^2 -> 0.52655681 | J6: SSE Orde 2 | K6: =SUM(H3:H9) -> 10.510184
A7: 20 | B7: 120.2 | C7: =K2*(1-EXP(-K3*A7)) -> 121.8986 | D7: =B7-C7 -> -1.6986036 | E7: =D7^2 -> 2.8852542 | F7: =(K4*A7*K2^2)/(1+K4*A7*K2) -> 120.07167 | G7: =B7-F7 -> 0.12832706 | H7: =G7^2 -> 0.016467834 | J7: SST Orde 1 | K7: {=SUM((Table3[Concentration EFB 2 mm (Ct1)]-AVERAGE(Table3[Concentration EFB 2 mm (Ct1)]))^2)} -> 12216.417
A8: 25 | B8: 121.6 | C8: =K2*(1-EXP(-K3*A8)) -> 121.89992 | D8: =B8-C8 -> -0.29991876 | E8: =D8^2 -> 0.089951264 | F8: =(K4*A8*K2^2)/(1+K4*A8*K2) -> 120.43294 | G8: =B8-F8 -> 1.1670624 | H8: =G8^2 -> 1.3620347 | J8: SST Orde 2 | K8: {=SUM((Table3[Concentration EFB 2 mm (Ct1)]-AVERAGE(Table3[Concentration EFB 2 mm (Ct1)]))^2)} -> 12216.417
A9: 30 | B9: 121.9 | C9: =K2*(1-EXP(-K3*A9)) -> 121.9 | D9: =B9-C9 -> 4.7261335e-06 | E9: =D9^2 -> 2.2336338e-11 | F9: =(K4*A9*K2^2)/(1+K4*A9*K2) -> 120.67499 | G9: =B9-F9 -> 1.2250092 | H9: =G9^2 -> 1.5006475 | J9: R^2 Orde 1 | K9: =1-(K5/K7) -> 0.99674561
J10: R^2 Orde 2 | K10: =1-(K6/K8) -> 0.99913967
D28: Sulfur
A29: Time (min) | B29: Concentration (Ct1) | C29: Orde 1 (Ct2) | D29: Error 1 | E29: Error^2 1 | F29: Orde 2 (Ct3) | G29: Error 2 | H29: Error^2 2 | J29: Csat | K29: 8.7
A30: 0 | B30: 0 | C30: 0 | D30: 0 | E30: 0 | F30: 0 | G30: 0 | H30: 0 | J30: K1 | K30: 7.0598493
A31: 5 | B31: 8 | C31: =K29*(1-EXP(-K30*A31)) -> 8.7 | D31: =B31-C31 -> -0.7 | E31: =D31^2 -> 0.49 | F31: =(K31*A31*K29^2)/(1+K31*A31*K29) -> 7.9756222 | G31: =B31-F31 -> 0.024377797 | H31: =G31^2 -> 0.00059427699 | J31: K2 | K31: 0.25311051
A32: 10 | B32: 8.2 | C32: =K29*(1-EXP(-K30*A32)) -> 8.7 | D32: =B32-C32 -> -0.5 | E32: =D32^2 -> 0.25 | F32: =(K31*A32*K29^2)/(1+K31*A32*K29) -> 8.3220779 | G32: =B32-F32 -> -0.12207786 | H32: =G32^2 -> 0.014903004 | J32: SSE Orde 1 | K32: =SUM(E30:E36) -> 0.87
A33: 15 | B33: 8.4 | C33: =K29*(1-EXP(-K30*A33)) -> 8.7 | D33: =B33-C33 -> -0.3 | E33: =D33^2 -> 0.09 | F33: =(K31*A33*K29^2)/(1+K31*A33*K29) -> 8.4443502 | G33: =B33-F33 -> -0.044350154 | H33: =G33^2 -> 0.0019669362 | J33: SSE Orde 2 | K33: =SUM(H30:H36) -> 0.058432663
A34: 20 | B34: 8.5 | C34: =K29*(1-EXP(-K30*A34)) -> 8.7 | D34: =B34-C34 -> -0.2 | E34: =D34^2 -> 0.04 | F34: =(K31*A34*K29^2)/(1+K31*A34*K29) -> 8.5068436 | G34: =B34-F34 -> -0.0068436387 | H34: =G34^2 -> 4.6835391e-05 | J34: SST Orde 1 | K34: {=SUM((B30:B36-AVERAGE(B30:B36))^2)} -> 61.108571
A35: 25 | B35: 8.7 | C35: =K29*(1-EXP(-K30*A35)) -> 8.7 | D35: =B35-C35 -> 0 | E35: =D35^2 -> 0 | F35: =(K31*A35*K29^2)/(1+K31*A35*K29) -> 8.5447857 | G35: =B35-F35 -> 0.1552143 | H35: =G35^2 -> 0.024091479 | J35: SST Orde 2 | K35: {=SUM((B30:B36-AVERAGE(B30:B36))^2)} -> 61.108571
A36: 30 | B36: 8.7 | C36: =K29*(1-EXP(-K30*A36)) -> 8.7 | D36: =B36-C36 -> 0 | E36: =D36^2 -> 0 | F36: =(K31*A36*K29^2)/(1+K31*A36*K29) -> 8.570269 | G36: =B36-F36 -> 0.129731 | H36: =G36^2 -> 0.016830132 | J36: R^2 Orde 1 | K36: =1-(K32/K34) -> 0.98576304
J37: R^2 Orde 2 | K37: =1-(K33/K35) -> 0.99904379
D55: Magnesium
A56: Time (t) | B56: Concentration (Ct1) | C56: Orde 1 (Ct2) | D56: Error 1 | E56: Error^2 1 | F56: Orde 2 (Ct3) | G56: Error 2 | H56: Error^2 2 | J56: Csat | K56: 76.7
A57: 0 | B57: 0 | C57: 0 | D57: 0 | E57: 0 | F57: 0 | G57: 0 | H57: 0 | J57: K1 | K57: 5.7725385
A58: 5 | B58: 66.9 | C58: =K56*(1-EXP(-K57*A58)) -> 76.7 | D58: =B58-C58 -> -9.8 | E58: =D58^2 -> 96.04 | F58: =(K58*A58*K56^2)/(1+K58*A58*K56) -> 63.509264 | G58: =B58-F58 -> 3.3907356 | H58: =G58^2 -> 11.497088 | J58: K2 | K58: 0.012554595
A59: 10 | B59: 67.7 | C59: =K56*(1-EXP(-K57*A59)) -> 76.7 | D59: =B59-C59 -> -9 | E59: =D59^2 -> 81 | F59: =(K58*A59*K56^2)/(1+K58*A59*K56) -> 69.484147 | G59: =B59-F59 -> -1.7841472 | H59: =G59^2 -> 3.1831811 | J59: SSE Orde 1 | K59: =SUM(E57:E63) -> 317.85
A60: 15 | B60: 69.3 | C60: =K56*(1-EXP(-K57*A60)) -> 76.7 | D60: =B60-C60 -> -7.4 | E60: =D60^2 -> 54.76 | F60: =(K58*A60*K56^2)/(1+K58*A60*K56) -> 71.73369 | G60: =B60-F60 -> -2.4336898 | H60: =G60^2 -> 5.9228458 | J60: SSE Orde 2 | K60: =SUM(H57:H63) -> 46.751356
A61: 20 | B61: 69.8 | C61: =K56*(1-EXP(-K57*A61)) -> 76.7 | D61: =B61-C61 -> -6.9 | E61: =D61^2 -> 47.61 | F61: =(K58*A61*K56^2)/(1+K58*A61*K56) -> 72.913981 | G61: =B61-F61 -> -3.1139813 | H61: =G61^2 -> 9.6968797 | J61: SST Orde 1 | K61: {=SUM((B57:B63-AVERAGE(B57:B63))^2)} -> 4278.4543
A62: 25 | B62: 70.5 | C62: =K56*(1-EXP(-K57*A62)) -> 76.7 | D62: =B62-C62 -> -6.2 | E62: =D62^2 -> 38.44 | F62: =(K58*A62*K56^2)/(1+K58*A62*K56) -> 73.640986 | G62: =B62-F62 -> -3.1409856 | H62: =G62^2 -> 9.8657906 | J62: SST Orde 2 | K62: {=SUM((B57:B63-AVERAGE(B57:B63))^2)} -> 4278.4543
A63: 30 | B63: 76.7 | C63: =K56*(1-EXP(-K57*A63)) -> 76.7 | D63: =B63-C63 -> 0 | E63: =D63^2 -> 0 | F63: =(K58*A63*K56^2)/(1+K58*A63*K56) -> 74.133763 | G63: =B63-F63 -> 2.5662368 | H63: =G63^2 -> 6.5855713 | J63: R^2 Orde 1 | K63: =1-(K59/K61) -> 0.92570915
J64: R^2 Orde 2 | K64: =1-(K60/K62) -> 0.98907284
D82: Silicon
A83: Time (min) | B83: Concentration (Ct1) | C83: Orde 1 (Ct2) | D83: Error 1 | E83: Error^2 1 | F83: Orde 2 (Ct3) | G83: Error 2 | H83: Error^2 2 | J83: Csat | K83: 5.6
A84: 0 | B84: 0 | C84: 0 | D84: 0 | E84: 0 | F84: 0 | G84: 0 | H84: 0 | J84: K1 | K84: 6.3002856
A85: 5 | B85: 4.7 | C85: =K83*(1-EXP(-K84*A85)) -> 5.6 | D85: =B85-C85 -> -0.9 | E85: =D85^2 -> 0.81 | F85: =(K85*A85*K83^2)/(1+K85*A85*K83) -> 4.684323 | G85: =B85-F85 -> 0.015677048 | H85: =G85^2 -> 0.00024576982 | J85: K2 | K85: 0.18270333
A86: 10 | B86: 5 | C86: =K83*(1-EXP(-K84*A86)) -> 5.6 | D86: =B86-C86 -> -0.6 | E86: =D86^2 -> 0.36 | F86: =(K85*A86*K83^2)/(1+K85*A86*K83) -> 5.1013973 | G86: =B86-F86 -> -0.10139727 | H86: =G86^2 -> 0.010281407 | J86: SSE Orde 1 | K86: =SUM(E84:E90) -> 1.44
A87: 25 | B87: 5.1 | C87: =K83*(1-EXP(-K84*A87)) -> 5.6 | D87: =B87-C87 -> -0.5 | E87: =D87^2 -> 0.25 | F87: =(K85*A87*K83^2)/(1+K85*A87*K83) -> 5.3893031 | G87: =B87-F87 -> -0.28930312 | H87: =G87^2 -> 0.083696295 | J87: SSE Orde 2 | K87: =SUM(H84:H90) -> 0.16359041
A88: 20 | B88: 5.5 | C88: =K83*(1-EXP(-K84*A88)) -> 5.6 | D88: =B88-C88 -> -0.1 | E88: =D88^2 -> 0.01 | F88: =(K85*A88*K83^2)/(1+K85*A88*K83) -> 5.3390831 | G88: =B88-F88 -> 0.16091689 | H88: =G88^2 -> 0.025894245 | J88: SST Orde 1 | K88: {=SUM((B84:B90-AVERAGE(B84:B90))^2)} -> 24.108571
A89: 25 | B89: 5.5 | C89: =K83*(1-EXP(-K84*A89)) -> 5.6 | D89: =B89-C89 -> -0.1 | E89: =D89^2 -> 0.01 | F89: =(K85*A89*K83^2)/(1+K85*A89*K83) -> 5.3893031 | G89: =B89-F89 -> 0.11069688 | H89: =G89^2 -> 0.012253799 | J89: SST Orde 2 | K89: {=SUM((B84:B90-AVERAGE(B84:B90))^2)} -> 24.108571
A90: 30 | B90: 5.6 | C90: =K83*(1-EXP(-K84*A90)) -> 5.6 | D90: =B90-C90 -> 0 | E90: =D90^2 -> 0 | F90: =(K85*A90*K83^2)/(1+K85*A90*K83) -> 5.4233113 | G90: =B90-F90 -> 0.1766887 | H90: =G90^2 -> 0.031218898 | J90: R^2 Orde 1 | K90: =1-(K86/K88) -> 0.94027021
J91: R^2 Orde 2 | K91: =1-(K87/K89) -> 0.99321443
...

Sheet Hasil EFB 0.85mm
D1: Calcium
A2: Time (min) | B2: Concentration EFB 0,85mm (Ct1) | C2: Orde 1 (Ct2) | D2: Error 1 | E2: Error ^2 1 | F2: Orde 2 (Ct3) | G2: Error 2 | H2: Error^2 2 | J2: Csat | K2: 132.6
A3: 0 | B3: 0 | C3: 0 | D3: 0 | E3: 0 | F3: 0 | G3: 0 | H3: 0 | J3: K1 | K3: 0.24904654
A4: 5 | B4: 94.7 | C4: =K2*(1-EXP((-K3*A4))) -> 94.427918 | D4: =B4-C4 -> 0.27208161 | E4: =D4^2 -> 0.074028401 | F4: =(K4*A4*K2^2)/(1+K4*A4*K2) -> 103.49863 | G4: =B4-F4 -> -8.7986275 | H4: =G4^2 -> 77.415846 | J4: K2 | K4: 0.0053642325
A5: 10 | B5: 124.8 | C5: =K2*(1-EXP((-K3*A5))) -> 121.61125 | D5: =B5-C5 -> 3.1887467 | E5: =D5^2 -> 10.168106 | F5: =(K4*A5*K2^2)/(1+K4*A5*K2) -> 116.25581 | G5: =B5-F5 -> 8.544195 | H5: =G5^2 -> 73.003267 | J5: SSE Orde 1 | K5: =SUM(E3:E9) -> 123.09594
A6: 15 | B6: 124.4 | C6: =K2*(1-EXP((-K3*A6))) -> 129.43663 | D6: =B6-C6 -> -5.0366264 | E6: =D6^2 -> 25.367606 | F6: =(K4*A6*K2^2)/(1+K4*A6*K2) -> 121.237 | G6: =B6-F6 -> 3.1629953 | H6: =G6^2 -> 10.004539 | J6: SSE Orde 2 | K6: =SUM(H3:H9) -> 197.1445
A7: 20 | B7: 125.1 | C7: =K2*(1-EXP((-K3*A7))) -> 131.68935 | D7: =B7-C7 -> -6.5893473 | E7: =D7^2 -> 43.419497 | F7: =(K4*A7*K2^2)/(1+K4*A7*K2) -> 123.89118 | G7: =B7-F7 -> 1.2088194 | H7: =G7^2 -> 1.4612442 | J7: SST Orde 1 | K7: {=SUM((Table2[Concentration EFB 0,85mm (Ct1)]-AVERAGE(Table2[Concentration EFB 0,85mm (Ct1)]))^2)} -> 13485.28
A8: 25 | B8: 125.7 | C8: =K2*(1-EXP((-K3*A8))) -> 132.33785 | D8: =B8-C8 -> -6.6378468 | E8: =D8^2 -> 44.06101 | F8: =(K4*A8*K2^2)/(1+K4*A8*K2) -> 125.54021 | G8: =B8-F8 -> 0.15978916 | H8: =G8^2 -> 0.025532575 | J8: SST Orde 2 | K8: {=SUM((Table2[Concentration EFB 0,85mm (Ct1)]-AVERAGE(Table2[Concentration EFB 0,85mm (Ct1)]))^2)} -> 13485.28
A9: 30 | B9: 132.6 | C9: =K2*(1-EXP((-K3*A9))) -> 132.52453 | D9: =B9-C9 -> 0.075467062 | E9: =D9^2 -> 0.0056952774 | F9: =(K4*A9*K2^2)/(1+K4*A9*K2) -> 126.66417 | G9: =B9-F9 -> 5.9358295 | H9: =G9^2 -> 35.234071 | J9: R^2 Orde 1 | K9: =1-(K5/K7) -> 0.99087183
J10: R^2 Orde 2 | K10: =1-(K6/K8) -> 0.98538076
D27: Sulfur
A28: Time (min) | B28: Concentration (Ct1) | C28: Orde 1 | D28: Error 1 | E28: Error^2 1 | F28: Orde 2 | G28: Error 2 | H28: Error^2 2 | J28: Csat | K28: 9.3
A29: 0 | B29: 0 | C29: 0 | D29: 0 | E29: 0 | F29: 0 | G29: 0 | H29: 0 | J29: K1 | K29: 5.9707657
A30: 5 | B30: 7.3 | C30: =K28*(1-EXP(-K29*A30)) -> 9.3 | D30: =B30-C30 -> -2 | E30: =D30^2 -> 4 | F30: =(K30*A30*K28^2)/(1+K30*A30*K28) -> 7.4480727 | G30: =B30-F30 -> -0.14807267 | H30: =G30^2 -> 0.021925516 | J30: K2 | K30: 0.086490222
A31: 10 | B31: 8.5 | C31: =K28*(1-EXP(-K29*A31)) -> 9.3 | D31: =B31-C31 -> -0.8 | E31: =D31^2 -> 0.64 | F31: =(K30*A31*K28^2)/(1+K30*A31*K28) -> 8.2716474 | G31: =B31-F31 -> 0.22835261 | H31: =G31^2 -> 0.052144913 | J31: SSE Orde 1 | K31: =SUM(E29:E35) -> 5.93
A32: 15 | B32: 8.5 | C32: =K28*(1-EXP(-K29*A32)) -> 9.3 | D32: =B32-C32 -> -0.8 | E32: =D32^2 -> 0.64 | F32: =(K30*A32*K28^2)/(1+K30*A32*K28) -> 8.5881955 | G32: =B32-F32 -> -0.08819554 | H32: =G32^2 -> 0.0077784533 | J32: SSE Orde 2 | K32: =SUM(H29:H35) -> 0.24469498
A33: 20 | B33: 8.6 | C33: =K28*(1-EXP(-K29*A33)) -> 9.3 | D33: =B33-C33 -> -0.7 | E33: =D33^2 -> 0.49 | F33: =(K30*A33*K28^2)/(1+K30*A33*K28) -> 8.7557324 | G33: =B33-F33 -> -0.15573235 | H33: =G33^2 -> 0.024252565 | J33: SST Orde 1 | K33: {=SUM((B29:B35-AVERAGE(B29:B35))^2)} -> 64.42
A34: 25 | B34: 8.9 | C34: =K28*(1-EXP(-K29*A34)) -> 9.3 | D34: =B34-C34 -> -0.4 | E34: =D34^2 -> 0.16 | F34: =(K30*A34*K28^2)/(1+K30*A34*K28) -> 8.8594291 | G34: =B34-F34 -> 0.040570861 | H34: =G34^2 -> 0.0016459948 | J34: SST Orde 2 | K34: {=SUM((B29:B35-AVERAGE(B29:B35))^2)} -> 64.42
A35: 30 | B35: 9.3 | C35: =K28*(1-EXP(-K29*A35)) -> 9.3 | D35: =B35-C35 -> 0 | E35: =D35^2 -> 0 | F35: =(K30*A35*K28^2)/(1+K30*A35*K28) -> 8.9299358 | G35: =B35-F35 -> 0.37006424 | H35: =G35^2 -> 0.13694754 | J35: R^2 Orde 1 | K35: =1-(K31/K33) -> 0.90794784
J36: R^2 Orde 2 | K36: =1-(K32/K34) -> 0.99620157
D54: Magnesium
A55: Time (min) | B55: Concentration (Ct1) | C55: Orde 1 (Ct2) | D55: Error 1 | E55: Error^2 1 | F55: Orde 2 (Ct3) | G55: Error 2 | H55: Error^2 2
A56: 0 | B56: 0 | C56: 0 | D56: 0 | E56: 0 | F56: 0 | G56: 0 | H56: 0 | J56: Csat | K56: 95.7
A57: 5 | B57: 67.8 | C57: =K56*(1-EXP(-K57*A57)) -> 95.7 | D57: =B57-C57 -> -27.9 | E57: =D57^2 -> 778.41 | F57: =(K58*A57*K56^2)/(1+K58*A57*K56) -> 72.966442 | G57: =B57-F57 -> -5.1664415 | H57: =G57^2 -> 26.692118 | J57: K1 | K57: 5.8882085
A58: 10 | B58: 88.2 | C58: =K56*(1-EXP(-K57*A58)) -> 95.7 | D58: =B58-C58 -> -7.5 | E58: =D58^2 -> 56.25 | F58: =(K58*A58*K56^2)/(1+K58*A58*K56) -> 82.801159 | G58: =B58-F58 -> 5.3988406 | H58: =G58^2 -> 29.14748 | J58: K2 | K58: 0.0067077027
A59: 15 | B59: 87 | C59: =K56*(1-EXP(-K57*A59)) -> 95.7 | D59: =B59-C59 -> -8.7 | E59: =D59^2 -> 75.69 | F59: =(K58*A59*K56^2)/(1+K58*A59*K56) -> 86.696252 | G59: =B59-F59 -> 0.30374784 | H59: =G59^2 -> 0.092262747 | J59: SSE Orde 1 | K59: =SUM(E56:E62) -> 978.13
A60: 20 | B60: 89.4 | C60: =K56*(1-EXP(-K57*A60)) -> 95.7 | D60: =B60-C60 -> -6.3 | E60: =D60^2 -> 39.69 | F60: =(K58*A60*K56^2)/(1+K58*A60*K56) -> 88.784532 | G60: =B60-F60 -> 0.61546795 | H60: =G60^2 -> 0.3788008 | J60: SSE Orde 2 | K60: =SUM(H56:H62) -> 78.726094
A61: 25 | B61: 90.4 | C61: =K56*(1-EXP(-K57*A61)) -> 95.7 | D61: =B61-C61 -> -5.3 | E61: =D61^2 -> 28.09 | F61: =(K58*A61*K56^2)/(1+K58*A61*K56) -> 90.086497 | G61: =B61-F61 -> 0.31350289 | H61: =G61^2 -> 0.098284061 | J61: SST Orde 1 | K61: {=SUM((B56:B62-AVERAGE(B56:B62))^2)} -> 6862.0543
A62: 30 | B62: 95.7 | C62: =K56*(1-EXP(-K57*A62)) -> 95.7 | D62: =B62-C62 -> 0 | E62: =D62^2 -> 0 | F62: =(K58*A62*K56^2)/(1+K58*A62*K56) -> 90.975897 | G62: =B62-F62 -> 4.7241029 | H62: =G62^2 -> 22.317148 | J62: SST Orde 2 | K62: {=SUM((B56:B62-AVERAGE(B56:B62))^2)} -> 6862.0543
J63: R^2 Orde 1 | K63: =1-(K59/K61) -> 0.85745814
J64: R^2 Orde 2 | K64: =1-(K60/K62) -> 0.98852733
D80: Silicon
A81: Time (min) | B81: Concentration (Ct1) | C81: Orde 1 (Ct2) | D81: Error 1 | E81: Error^2 1 | F81: Orde 2 (Ct2) | G81: Error 2 | H81: Error^2 2 | J81: Csat | K81: 5.09
A82: 0 | B82: 0 | C82: 0 | D82: 0 | E82: 0 | F82: 0 | G82: 0 | H82: 0 | J82: K1 | K82: 5.4154431
A83: 5 | B83: 3.59 | C83: =K81*(1-EXP(-K82*A83)) -> 5.09 | D83: =B83-C83 -> -1.5 | E83: =D83^2 -> 2.25 | F83: =(K83*A83*K81^2)/(1+K83*A83*K81) -> 3.4393563 | G83: =B83-F83 -> 0.15064365 | H83: =G83^2 -> 0.022693509 | J83: K2 | K83: 0.081872125
A84: 10 | B84: 3.69 | C84: =K81*(1-EXP(-K82*A84)) -> 5.09 | D84: =B84-C84 -> -1.4 | E84: =D84^2 -> 1.96 | F84: =(K83*A84*K81^2)/(1+K83*A84*K81) -> 4.1049578 | G84: =B84-F84 -> -0.41495777 | H84: =G84^2 -> 0.17218995 | J84: SSE Orde 1 | K84: =SUM(E82:E88) -> 5.17
A85: 15 | B85: 4.29 | C85: =K81*(1-EXP(-K82*A85)) -> 5.09 | D85: =B85-C85 -> -0.8 | E85: =D85^2 -> 0.64 | F85: =(K83*A85*K81^2)/(1+K83*A85*K81) -> 4.3880217 | G85: =B85-F85 -> -0.098021734 | H85: =G85^2 -> 0.0096082604 | J85: SSE Orde 2 | K85: =SUM(H82:H88) -> 0.36981236
A86: 20 | B86: 4.69 | C86: =K81*(1-EXP(-K82*A86)) -> 5.09 | D86: =B86-C86 -> -0.4 | E86: =D86^2 -> 0.16 | F86: =(K83*A86*K81^2)/(1+K83*A86*K81) -> 4.5447158 | G86: =B86-F86 -> 0.14528417 | H86: =G86^2 -> 0.021107491 | J86: SST Orde 1 | K86: {=SUM((B82:B88-AVERAGE(B82:B88))^2)} -> 17.9398
A87: 25 | B87: 4.69 | C87: =K81*(1-EXP(-K82*A87)) -> 5.09 | D87: =B87-C87 -> -0.4 | E87: =D87^2 -> 0.16 | F87: =(K83*A87*K81^2)/(1+K83*A87*K81) -> 4.6442215 | G87: =B87-F87 -> 0.045778455 | H87: =G87^2 -> 0.002095667 | J87: SST Orde 2 | K87: {=SUM((B82:B88-AVERAGE(B82:B88))^2)} -> 17.9398
A88: 30 | B88: 5.09 | C88: =K81*(1-EXP(-K82*A88)) -> 5.09 | D88: =B88-C88 -> 0 | E88: =D88^2 -> 0 | F88: =(K83*A88*K81^2)/(1+K83*A88*K81) -> 4.7130153 | G88: =B88-F88 -> 0.37698472 | H88: =G88^2 -> 0.14211748 | J88: R^2 Orde 1 | K88: =1-(K84/K86) -> 0.71181396
...

Sheet Ringkasan Hasil Analisis Logam
A1: EFB (mm) | B1: Logam | C1: Csat | D1: k1 | E1: k2 | F1: R^2 Orde 1 | G1: R^2 Orde 2 | H1: Model Terbaik
A2: 10 | B2: Iron | C2: ='Hasil EFB 10mm'!K164 -> 8.59 | D2: ='Hasil EFB 10mm'!K165 -> 0.095611713 | E2: ='Hasil EFB 10mm'!K166 -> 0.017543226 | F2: ='Hasil EFB 10mm'!K171 -> 0.87819037 | G2: ='Hasil EFB 10mm'!K172 -> -0.96518981 | H2: Orde 1
B3: Calcium | C3: ='Hasil EFB 10mm'!K2 -> 146.2 | D3: ='Hasil EFB 10mm'!K3 -> 0.36902977 | E3: ='Hasil EFB 10mm'!K4 -> 0.008233212 | F3: ='Hasil EFB 10mm'!K9 -> 0.98291724 | G3: ='Hasil EFB 10mm'!K10 -> 0.99732105 | H3: Orde 2
B4: Magnesium | C4: ='Hasil EFB 10mm'!K55 -> 97.3 | D4: ='Hasil EFB 10mm'!K56 -> 6.2060965 | E4: ='Hasil EFB 10mm'!K57 -> 0.007197754 | F4: ='Hasil EFB 10mm'!K62 -> 0.87539546 | G4: ='Hasil EFB 10mm'!K63 -> 0.9865011 | H4: Orde 2
B5: Sodium | C5: ='Hasil EFB 10mm'!K109 -> 2.6 | D5: ='Hasil EFB 10mm'!K110 -> 4.9124859 | E5: ='Hasil EFB 10mm'!K111 -> 0.069659603 | F5: ='Hasil EFB 10mm'!K116 -> 0.068373664 | G5: ='Hasil EFB 10mm'!K117 -> 0.92295558 | H5: Orde 2
B6: Potassium | C6: ='Hasil EFB 10mm'!K218 -> 570.7 | D6: ='Hasil EFB 10mm'!K219 -> 0.31217327 | E6: ='Hasil EFB 10mm'!K220 -> 0.001973912 | F6: ='Hasil EFB 10mm'!K225 -> 0.99843817 | G6: ='Hasil EFB 10mm'!K226 -> 0.98725605 | H6: =IF(F6>G6,"Orde 1",IF(G6>F6,"Orde 2")) -> Orde 1
B7: Phosfor | C7: ='Hasil EFB 10mm'!K136 -> 23.2 | D7: ='Hasil EFB 10mm'!K137 -> 0.25490255 | E7: ='Hasil EFB 10mm'!K138 -> 0.035076371 | F7: ='Hasil EFB 10mm'!K143 -> 0.9998495 | G7: ='Hasil EFB 10mm'!K144 -> 0.97785464 | H7: Orde 1
B8: Silicon | C8: ='Hasil EFB 10mm'!K82 -> 5.19 | D8: ='Hasil EFB 10mm'!K83 -> 5.6388017 | E8: ='Hasil EFB 10mm'!K84 -> 0.05843196 | F8: ='Hasil EFB 10mm'!K89 -> 0.51169421 | G8: ='Hasil EFB 10mm'!K90 -> 0.90906915 | H8: Orde 2
B9: Alumunium | C9: ='Hasil EFB 10mm'!K243 -> 1.6 | D9: ='Hasil EFB 10mm'!K244 -> 0.12504827 | E9: ='Hasil EFB 10mm'!K245 -> 0.17722517 | F9: ='Hasil EFB 10mm'!K250 -> 0.95603409 | G9: ='Hasil EFB 10mm'!K251 -> 0.97601109 | H9: =IF(F9>G9,"Orde 1",IF(G9>F9,"Orde 2")) -> Orde 2
B10: Titanium | C10: ='Hasil EFB 10mm'!K191 -> 0.1 | D10: ='Hasil EFB 10mm'!K192 -> 5368709.2 | E10: ='Hasil EFB 10mm'!K193 -> 0.26738719 | F10: ='Hasil EFB 10mm'!K198 -> 1 | G10: ='Hasil EFB 10mm'!K199 -> -1.2819328 | H10: =IF(F10>G10,"Orde 1",IF(G10>F10,"Orde 2")) -> Orde 1
B11: Sulfur | C11: ='Hasil EFB 10mm'!K28 -> 7.4 | D11: ='Hasil EFB 10mm'!K29 -> 7.4 | E11: ='Hasil EFB 10mm'!K30 -> 0.66582618 | F11: ='Hasil EFB 10mm'!K35 -> 0.99147491 | G11: ='Hasil EFB 10mm'!K36 -> 0.99702692 | H11: =IF(F11>G11,"Orde 1",IF(G11>F11,"Orde 2")) -> Orde 2
B12: Chloride | C12: 3.19 | D12: 0.074914262 | E12: 0.044519642 | F12: 0.93423286 | G12: 0.9828343 | H12: =IF(F12>G12,"Orde 1",IF(G12>F12,"Orde 2")) -> Orde 2
A13: 2 | B13: Iron | C13: ='Hasil EFB 2mm'!K165 -> 8.59 | D13: ='Hasil EFB 2mm'!K166 -> 0.21741957 | E13: ='Hasil EFB 2mm'!K167 -> 0.06531033 | F13: ='Hasil EFB 2mm'!K172 -> 0.9559309 | G13: ='Hasil EFB 2mm'!K173 -> 0.99123975 | H13: =IF(F13>G13,"Orde 1",IF(G13>F13,"Orde 2")) -> Orde 2
B14: Calcium | C14: ='Hasil EFB 2mm'!K2 -> 121.9 | D14: ='Hasil EFB 2mm'!K3 -> 0.56885347 | E14: ='Hasil EFB 2mm'!K4 -> 0.026937232 | F14: ='Hasil EFB 2mm'!K9 -> 0.99674561 | G14: ='Hasil EFB 2mm'!K10 -> 0.99913967 | H14: =IF(F14>G14,"Orde 1",IF(G14>F14,"Orde 2")) -> Orde 2
B15: Magnesium | C15: ='Hasil EFB 2mm'!K56 -> 76.7 | D15: ='Hasil EFB 2mm'!K57 -> 5.7725385 | E15: ='Hasil EFB 2mm'!K58 -> 0.012554595 | F15: ='Hasil EFB 2mm'!K63 -> 0.92570915 | G15: ='Hasil EFB 2mm'!K64 -> 0.98907284 | H15: =IF(F15>G15,"Orde 1",IF(G15>F15,"Orde 2")) -> Orde 2
B16: Sodium | C16: ='Hasil EFB 2mm'!K111 -> 17.2 | D16: ='Hasil EFB 2mm'!K112 -> 0.30714022 | E16: ='Hasil EFB 2mm'!K113 -> 0.05504033 | F16: ='Hasil EFB 2mm'!K118 -> 0.981711 | G16: ='Hasil EFB 2mm'!K119 -> 0.99549648 | H16: =IF(F16>G16,"Orde 1",IF(G16>F16,"Orde 2")) -> Orde 2
B17: Potassium | C17: ='Hasil EFB 2mm'!K219 -> 624.5 | D17: ='Hasil EFB 2mm'!K220 -> 0.53113476 | E17: ='Hasil EFB 2mm'!K221 -> 0.0036061574 | F17: ='Hasil EFB 2mm'!K226 -> 0.99047901 | G17: ='Hasil EFB 2mm'!K227 -> 0.99763798 | H17: =IF(F17>G17,"Orde 1",IF(G17>F17,"Orde 2")) -> Orde 2
B18: Phosfor | C18: ='Hasil EFB 2mm'!K138 -> 23.9 | D18: ='Hasil EFB 2mm'!K139 -> 0.31200172 | E18: ='Hasil EFB 2mm'!K140 -> 0.033644002 | F18: ='Hasil EFB 2mm'!K145 -> 0.94735697 | G18: ='Hasil EFB 2mm'!K146 -> 0.98790331 | H18: =IF(F18>G18,"Orde 1",IF(G18>F18,"Orde 2")) -> Orde 2
B19: Silicon | C19: ='Hasil EFB 2mm'!K83 -> 5.6 | D19: ='Hasil EFB 2mm'!K84 -> 6.3002856 | E19: ='Hasil EFB 2mm'!K85 -> 0.18270333 | F19: ='Hasil EFB 2mm'!K90 -> 0.94027021 | G19: ='Hasil EFB 2mm'!K91 -> 0.99321443 | H19: =IF(F19>G19,"Orde 1",IF(G19>F19,"Orde 2")) -> Orde 2
B20: Alumunium | C20: ='Hasil EFB 2mm'!K245 -> 0.8 | D20: ='Hasil EFB 2mm'!K246 -> 0.19200499 | E20: ='Hasil EFB 2mm'!K247 -> 0.64587357 | F20: ='Hasil EFB 2mm'!K252 -> 0.99268701 | G20: ='Hasil EFB 2mm'!K253 -> 0.96561937 | H20: =IF(F20>G20,"Orde 1",IF(G20>F20,"Orde 2")) -> Orde 1
B21: Titanium | C21: ='Hasil EFB 2mm'!K192 -> 0.1 | D21: ='Hasil EFB 2mm'!K193 -> 5368709.2 | E21: ='Hasil EFB 2mm'!K194 -> 5368709.2 | F21: ='Hasil EFB 2mm'!K199 -> 1 | G21: ='Hasil EFB 2mm'!K200 -> 1 | H21: =IF(F21=G21, "Orde 1 dan Orde 2", IF(ABS(1-F21)<ABS(1-G21), "Orde 1", "Orde 2")) -> Orde 1
B22: Sulfur | C22: ='Hasil EFB 2mm'!K29 -> 8.7 | D22: ='Hasil EFB 2mm'!K30 -> 7.0598493 | E22: ='Hasil EFB 2mm'!K31 -> 0.25311051 | F22: ='Hasil EFB 2mm'!K36 -> 0.98576304 | G22: ='Hasil EFB 2mm'!K37 -> 0.99904379 | H22: =IF(F22>G22,"Orde 1",IF(G22>F22,"Orde 2")) -> Orde 2
B23: Chloride | C23: 4.89 | D23: 0.048236692 | E23: 0.014893192 | F23: 0.87138303 | G23: 0.77564229 | H23: =IF(F23>G23,"Orde 1",IF(G23>F23,"Orde 2")) -> Orde 1
A24: 0.85 | B24: Iron | C24: ='Hasil EFB 0.85mm'!K163 -> 8.89 | D24: ='Hasil EFB 0.85mm'!K164 -> 0.14641933 | E24: ='Hasil EFB 0.85mm'!K165 -> 0.039246016 | F24: ='Hasil EFB 0.85mm'!K170 -> 0.99753086 | G24: ='Hasil EFB 0.85mm'!K171 -> 0.9648676 | H24: =IF(F24>G24,"Orde 1",IF(G24>F24,"Orde 2")) -> Orde 1
B25: Calcium | C25: ='Hasil EFB 0.85mm'!K2 -> 132.6 | D25: ='Hasil EFB 0.85mm'!K3 -> 0.24904654 | E25: ='Hasil EFB 0.85mm'!K4 -> 0.0053642325 | F25: ='Hasil EFB 0.85mm'!K9 -> 0.99087183 | G25: ='Hasil EFB 0.85mm'!K10 -> 0.98538076 | H25: =IF(F25>G25,"Orde 1",IF(G25>F25,"Orde 2")) -> Orde 1
B26: Magnesium | C26: ='Hasil EFB 0.85mm'!K56 -> 95.7 | D26: ='Hasil EFB 0.85mm'!K57 -> 5.8882085 | E26: ='Hasil EFB 0.85mm'!K58 -> 0.0067077027 | F26: ='Hasil EFB 0.85mm'!K63 -> 0.85745814 | G26: ='Hasil EFB 0.85mm'!K64 -> 0.98852733 | H26: =IF(F26>G26,"Orde 1",IF(G26>F26,"Orde 2")) -> Orde 2
B27: Sodium | C27: ='Hasil EFB 0.85mm'!K108 -> 17.5 | D27: ='Hasil EFB 0.85mm'!K109 -> 0.38593791 | E27: ='Hasil EFB 0.85mm'!K110 -> 0.074296685 | F27: ='Hasil EFB 0.85mm'!K115 -> 0.97954551 | G27: ='Hasil EFB 0.85mm'!K116 -> 0.99381168 | H27: =IF(F27>G27,"Orde 1",IF(G27>F27,"Orde 2")) -> Orde 2
B28: Potassium | C28: ='Hasil EFB 0.85mm'!K218 -> 668.6 | D28: ='Hasil EFB 0.85mm'!K219 -> 0.20322988 | E28: ='Hasil EFB 0.85mm'!K220 -> 0.00082061263 | F28: ='Hasil EFB 0.85mm'!K225 -> 0.97143342 | G28: ='Hasil EFB 0.85mm'!K226 -> 0.9859945 | H28: =IF(F28>G28,"Orde 1",IF(G28>F28,"Orde 2")) -> Orde 2
B29: Phosfor | C29: ='Hasil EFB 0.85mm'!K136 -> 27.2 | D29: ='Hasil EFB 0.85mm'!K137 -> 0.17635548 | E29: ='Hasil EFB 0.85mm'!K138 -> 0.016241883 | F29: ='Hasil EFB 0.85mm'!K143 -> 0.95047818 | G29: ='Hasil EFB 0.85mm'!K144 -> 0.98251434 | H29: =IF(F29>G29,"Orde 1",IF(G29>F29,"Orde 2")) -> Orde 2
B30: Silicon | C30: ='Hasil EFB 0.85mm'!K81 -> 5.09 | D30: ='Hasil EFB 0.85mm'!K82 -> 5.4154431 | E30: ='Hasil EFB 0.85mm'!K83 -> 0.081872125 | F30: ='Hasil EFB 0.85mm'!K88 -> 0.71181396 | G30: ='Hasil EFB 0.85mm'!K89 -> 0.97938593 | H30: =IF(F30>G30,"Orde 1",IF(G30>F30,"Orde 2")) -> Orde 2
B31: Alumunium | C31: ='Hasil EFB 0.85mm'!K244 -> 0.9 | D31: ='Hasil EFB 0.85mm'!K245 -> 0.11952349 | E31: ='Hasil EFB 0.85mm'!K246 -> 0.28782426 | F31: ='Hasil EFB 0.85mm'!K251 -> 0.98012837 | G31: ='Hasil EFB 0.85mm'!K252 -> 0.95331319 | H31: =IF(F31>G31,"Orde 1",IF(G31>F31,"Orde 2")) -> Orde 1
B32: Titanium | C32: ='Hasil EFB 0.85mm'!K190 -> 0.1 | D32: ='Hasil EFB 0.85mm'!K191 -> 0.12872628 | E32: ='Hasil EFB 0.85mm'!K192 -> 2.5848255 | F32: ='Hasil EFB 0.85mm'!K197 -> 0.76876696 | G32: ='Hasil EFB 0.85mm'!K198 -> 0.6535153 | H32: =IF(F32>G32,"Orde 1",IF(G32>F32,"Orde 2")) -> Orde 1
B33: Sulfur | C33: ='Hasil EFB 0.85mm'!K28 -> 9.3 | D33: ='Hasil EFB 0.85mm'!K29 -> 5.9707657 | E33: ='Hasil EFB 0.85mm'!K30 -> 0.086490222 | F33: ='Hasil EFB 0.85mm'!K35 -> 0.90794784 | G33: ='Hasil EFB 0.85mm'!K36 -> 0.99620157 | H33: =IF(F33>G33,"Orde 1",IF(G33>F33,"Orde 2")) -> Orde 2
B34: Chloride | C34: 4.99 | D34: 0.053496561 | E34: 0.017232421 | F34: 0.86373951 | G34: 0.78255481 | H34: =IF(F34>G34,"Orde 1",IF(G34>F34,"Orde 2")) -> Orde 1
